Workbook
Name Slicer_Department: #N/A
Name Slicer_Reason: #N/A

Sheet DASHBOARD
A1: ATTENDANCE DASHBOARD

Sheet Data
A1: Employee ID | B1: Department | C1: Date | D1: Weekday | E1: Status | F1: Reason
A2: EMP001 | B2: Warehouse | C2: 46174 | D2: =TEXT(C2,"ddd") -> Mon | E2: Present
A3: EMP001 | B3: Warehouse | C3: 46175 | D3: =TEXT(C3,"ddd") -> Tue | E3: Present
A4: EMP001 | B4: Warehouse | C4: 46176 | D4: =TEXT(C4,"ddd") -> Wed | E4: Present
A5: EMP001 | B5: Warehouse | C5: 46177 | D5: =TEXT(C5,"ddd") -> Thu | E5: Present
A6: EMP001 | B6: Warehouse | C6: 46178 | D6: =TEXT(C6,"ddd") -> Fri | E6: Absent | F6: Unexcused
A7: EMP001 | B7: Warehouse | C7: 46181 | D7: =TEXT(C7,"ddd") -> Mon | E7: Present
A8: EMP001 | B8: Warehouse | C8: 46182 | D8: =TEXT(C8,"ddd") -> Tue | E8: Present
A9: EMP001 | B9: Warehouse | C9: 46183 | D9: =TEXT(C9,"ddd") -> Wed | E9: Present
A10: EMP001 | B10: Warehouse | C10: 46184 | D10: =TEXT(C10,"ddd") -> Thu | E10: Present
A11: EMP001 | B11: Warehouse | C11: 46185 | D11: =TEXT(C11,"ddd") -> Fri | E11: Present
A12: EMP001 | B12: Warehouse | C12: 46188 | D12: =TEXT(C12,"ddd") -> Mon | E12: Present
A13: EMP001 | B13: Warehouse | C13: 46189 | D13: =TEXT(C13,"ddd") -> Tue | E13: Absent | F13: Sick
A14: EMP001 | B14: Warehouse | C14: 46190 | D14: =TEXT(C14,"ddd") -> Wed | E14: Present
A15: EMP001 | B15: Warehouse | C15: 46191 | D15: =TEXT(C15,"ddd") -> Thu | E15: Present
A16: EMP001 | B16: Warehouse | C16: 46192 | D16: =TEXT(C16,"ddd") -> Fri | E16: Present
A17: EMP001 | B17: Warehouse | C17: 46195 | D17: =TEXT(C17,"ddd") -> Mon | E17: Present
A18: EMP001 | B18: Warehouse | C18: 46196 | D18: =TEXT(C18,"ddd") -> Tue | E18: Present
A19: EMP001 | B19: Warehouse | C19: 46197 | D19: =TEXT(C19,"ddd") -> Wed | E19: Present
A20: EMP001 | B20: Warehouse | C20: 46198 | D20: =TEXT(C20,"ddd") -> Thu | E20: Absent | F20: Sick
A21: EMP001 | B21: Warehouse | C21: 46199 | D21: =TEXT(C21,"ddd") -> Fri | E21: Present
A22: EMP001 | B22: Warehouse | C22: 46202 | D22: =TEXT(C22,"ddd") -> Mon | E22: Absent | F22: Vacation
A23: EMP001 | B23: Warehouse | C23: 46203 | D23: =TEXT(C23,"ddd") -> Tue | E23: Present
A24: EMP001 | B24: Warehouse | C24: 46204 | D24: =TEXT(C24,"ddd") -> Wed | E24: Present
A25: EMP001 | B25: Warehouse | C25: 46205 | D25: =TEXT(C25,"ddd") -> Thu | E25: Present
A26: EMP001 | B26: Warehouse | C26: 46206 | D26: =TEXT(C26,"ddd") -> Fri | E26: Present
A27: EMP001 | B27: Warehouse | C27: 46209 | D27: =TEXT(C27,"ddd") -> Mon | E27: Present
A28: EMP001 | B28: Warehouse | C28: 46210 | D28: =TEXT(C28,"ddd") -> Tue | E28: Present
A29: EMP001 | B29: Warehouse | C29: 46211 | D29: =TEXT(C29,"ddd") -> Wed | E29: Present
A30: EMP001 | B30: Warehouse | C30: 46212 | D30: =TEXT(C30,"ddd") -> Thu | E30: Present
A31: EMP001 | B31: Warehouse | C31: 46213 | D31: =TEXT(C31,"ddd") -> Fri | E31: Present
A32: EMP001 | B32: Warehouse | C32: 46216 | D32: =TEXT(C32,"ddd") -> Mon | E32: Present
A33: EMP001 | B33: Warehouse | C33: 46217 | D33: =TEXT(C33,"ddd") -> Tue | E33: Present
A34: EMP001 | B34: Warehouse | C34: 46218 | D34: =TEXT(C34,"ddd") -> Wed | E34: Present
A35: EMP001 | B35: Warehouse | C35: 46219 | D35: =TEXT(C35,"ddd") -> Thu | E35: Present
A36: EMP001 | B36: Warehouse | C36: 46220 | D36: =TEXT(C36,"ddd") -> Fri | E36: Absent | F36: Personal
A37: EMP001 | B37: Warehouse | C37: 46223 | D37: =TEXT(C37,"ddd") -> Mon | E37: Present
A38: EMP001 | B38: Warehouse | C38: 46224 | D38: =TEXT(C38,"ddd") -> Tue | E38: Present
A39: EMP001 | B39: Warehouse | C39: 46225 | D39: =TEXT(C39,"ddd") -> Wed | E39: Present
A40: EMP001 | B40: Warehouse | C40: 46226 | D40: =TEXT(C40,"ddd") -> Thu | E40: Present
...

Sheet Absence Breakdown by Dept
A1: Absence rate by department
A3: Department | B3: Scheduled Days | C3: Absent Days | D3: Absence Rate
A4: Warehouse | B4: =COUNTIFS(Data!$B:$B,$A4,Data!$C:$C,"<>") -> 510 | C4: =COUNTIFS(Data!$B:$B,$A4,Data!$E:$E,"Absent") -> 58 | D4: =IF($B4=0,0,$C4/$B4) -> 0.11372549
A5: Customer Service | B5: =COUNTIFS(Data!$B:$B,$A5,Data!$C:$C,"<>") -> 510 | C5: =COUNTIFS(Data!$B:$B,$A5,Data!$E:$E,"Absent") -> 39 | D5: =IF($B5=0,0,$C5/$B5) -> 0.076470588
A6: Sales | B6: =COUNTIFS(Data!$B:$B,$A6,Data!$C:$C,"<>") -> 510 | C6: =COUNTIFS(Data!$B:$B,$A6,Data!$E:$E,"Absent") -> 36 | D6: =IF($B6=0,0,$C6/$B6) -> 0.070588235
A7: Operations | B7: =COUNTIFS(Data!$B:$B,$A7,Data!$C:$C,"<>") -> 510 | C7: =COUNTIFS(Data!$B:$B,$A7,Data!$E:$E,"Absent") -> 26 | D7: =IF($B7=0,0,$C7/$B7) -> 0.050980392
A26: Absence reason by department
A28: Count of Reason | B28: Department
A29: Reason | B29: Customer Service | C29: Operations | D29: Sales | E29: Warehouse | F29: Grand Total
A30: Personal | B30: 8 | C30: 6 | D30: 4 | E30: 10 | F30: 28
A31: Sick | B31: 19 | C31: 9 | D31: 12 | E31: 17 | F31: 57
A32: Unexcused | B32: 5 | C32: 5 | D32: 6 | E32: 9 | F32: 25
A33: Vacation | B33: 7 | C33: 6 | D33: 14 | E33: 22 | F33: 49
A34: Grand Total | B34: 39 | C34: 26 | D34: 36 | E34: 58 | F34: 159
A55: Monthly absence trend by department
A57: Month | B57: Warehouse | C57: Customer Service | D57: Sales | E57: Operations
A58: 46174 | B58: =IFERROR(COUNTIFS(Data!$B:$B,B$57,Data!$E:$E,"Absent",Data!$C:$C,">="&$A58,Data!$C:$C,"<"&EDATE($A58,1))/COUNTIFS(Data!$B:$B,B$57,Data!$C:$C,">="&$A58,Data!$C:$C,"<"&EDATE($A58,1)),0) -> 0.12878788 | C58: =IFERROR(COUNTIFS(Data!$B:$B,C$57,Data!$E:$E,"Absent",Data!$C:$C,">="&$A58,Data!$C:$C,"<"&EDATE($A58,1))/COUNTIFS(Data!$B:$B,C$57,Data!$C:$C,">="&$A58,Data!$C:$C,"<"&EDATE($A58,1)),0) -> 0.090909091 | D58: =IFERROR(COUNTIFS(Data!$B:$B,D$57,Data!$E:$E,"Absent",Data!$C:$C,">="&$A58,Data!$C:$C,"<"&EDATE($A58,1))/COUNTIFS(Data!$B:$B,D$57,Data!$C:$C,">="&$A58,Data!$C:$C,"<"&EDATE($A58,1)),0) -> 0.060606061 | E58: =IFERROR(COUNTIFS(Data!$B:$B,E$57,Data!$E:$E,"Absent",Data!$C:$C,">="&$A58,Data!$C:$C,"<"&EDATE($A58,1))/COUNTIFS(Data!$B:$B,E$57,Data!$C:$C,">="&$A58,Data!$C:$C,"<"&EDATE($A58,1)),0) -> 0.022727273
A59: 46204 | B59: =IFERROR(COUNTIFS(Data!$B:$B,B$57,Data!$E:$E,"Absent",Data!$C:$C,">="&$A59,Data!$C:$C,"<"&EDATE($A59,1))/COUNTIFS(Data!$B:$B,B$57,Data!$C:$C,">="&$A59,Data!$C:$C,"<"&EDATE($A59,1)),0) -> 0.12318841 | C59: =IFERROR(COUNTIFS(Data!$B:$B,C$57,Data!$E:$E,"Absent",Data!$C:$C,">="&$A59,Data!$C:$C,"<"&EDATE($A59,1))/COUNTIFS(Data!$B:$B,C$57,Data!$C:$C,">="&$A59,Data!$C:$C,"<"&EDATE($A59,1)),0) -> 0.065217391 | D59: =IFERROR(COUNTIFS(Data!$B:$B,D$57,Data!$E:$E,"Absent",Data!$C:$C,">="&$A59,Data!$C:$C,"<"&EDATE($A59,1))/COUNTIFS(Data!$B:$B,D$57,Data!$C:$C,">="&$A59,Data!$C:$C,"<"&EDATE($A59,1)),0) -> 0.065217391 | E59: =IFERROR(COUNTIFS(Data!$B:$B,E$57,Data!$E:$E,"Absent",Data!$C:$C,">="&$A59,Data!$C:$C,"<"&EDATE($A59,1))/COUNTIFS(Data!$B:$B,E$57,Data!$C:$C,">="&$A59,Data!$C:$C,"<"&EDATE($A59,1)),0) -> 0.057971014
A60: 46235 | B60: =IFERROR(COUNTIFS(Data!$B:$B,B$57,Data!$E:$E,"Absent",Data!$C:$C,">="&$A60,Data!$C:$C,"<"&EDATE($A60,1))/COUNTIFS(Data!$B:$B,B$57,Data!$C:$C,">="&$A60,Data!$C:$C,"<"&EDATE($A60,1)),0) -> 0.13492063 | C60: =IFERROR(COUNTIFS(Data!$B:$B,C$57,Data!$E:$E,"Absent",Data!$C:$C,">="&$A60,Data!$C:$C,"<"&EDATE($A60,1))/COUNTIFS(Data!$B:$B,C$57,Data!$C:$C,">="&$A60,Data!$C:$C,"<"&EDATE($A60,1)),0) -> 0.079365079 | D60: =IFERROR(COUNTIFS(Data!$B:$B,D$57,Data!$E:$E,"Absent",Data!$C:$C,">="&$A60,Data!$C:$C,"<"&EDATE($A60,1))/COUNTIFS(Data!$B:$B,D$57,Data!$C:$C,">="&$A60,Data!$C:$C,"<"&EDATE($A60,1)),0) -> 0.055555556 | E60: =IFERROR(COUNTIFS(Data!$B:$B,E$57,Data!$E:$E,"Absent",Data!$C:$C,">="&$A60,Data!$C:$C,"<"&EDATE($A60,1))/COUNTIFS(Data!$B:$B,E$57,Data!$C:$C,">="&$A60,Data!$C:$C,"<"&EDATE($A60,1)),0) -> 0.079365079
A61: 46266 | B61: =IFERROR(COUNTIFS(Data!$B:$B,B$57,Data!$E:$E,"Absent",Data!$C:$C,">="&$A61,Data!$C:$C,"<"&EDATE($A61,1))/COUNTIFS(Data!$B:$B,B$57,Data!$C:$C,">="&$A61,Data!$C:$C,"<"&EDATE($A61,1)),0) -> 0.061403509 | C61: =IFERROR(COUNTIFS(Data!$B:$B,C$57,Data!$E:$E,"Absent",Data!$C:$C,">="&$A61,Data!$C:$C,"<"&EDATE($A61,1))/COUNTIFS(Data!$B:$B,C$57,Data!$C:$C,">="&$A61,Data!$C:$C,"<"&EDATE($A61,1)),0) -> 0.070175439 | D61: =IFERROR(COUNTIFS(Data!$B:$B,D$57,Data!$E:$E,"Absent",Data!$C:$C,">="&$A61,Data!$C:$C,"<"&EDATE($A61,1))/COUNTIFS(Data!$B:$B,D$57,Data!$C:$C,">="&$A61,Data!$C:$C,"<"&EDATE($A61,1)),0) -> 0.10526316 | E61: =IFERROR(COUNTIFS(Data!$B:$B,E$57,Data!$E:$E,"Absent",Data!$C:$C,">="&$A61,Data!$C:$C,"<"&EDATE($A61,1))/COUNTIFS(Data!$B:$B,E$57,Data!$C:$C,">="&$A61,Data!$C:$C,"<"&EDATE($A61,1)),0) -> 0.043859649
A80: Weekday absence trend
A82: Weekday | B82: Total Absence | C82: Total Records | D82: Absence Rate
A83: Mon | B83: =COUNTIFS(Data!D:D,'Absence Breakdown by Dept'!A83,Data!E:E,"Absent") -> 34 | C83: =COUNTIF(Data!D:D,'Absence Breakdown by Dept'!A83) -> 408 | D83: =B83/C83 -> 0.083333333
A84: Tue | B84: =COUNTIFS(Data!D:D,'Absence Breakdown by Dept'!A84,Data!E:E,"Absent") -> 32 | C84: =COUNTIF(Data!D:D,'Absence Breakdown by Dept'!A84) -> 408 | D84: =B84/C84 -> 0.078431373
A85: Wed | B85: =COUNTIFS(Data!D:D,'Absence Breakdown by Dept'!A85,Data!E:E,"Absent") -> 27 | C85: =COUNTIF(Data!D:D,'Absence Breakdown by Dept'!A85) -> 408 | D85: =B85/C85 -> 0.066176471
A86: Thu | B86: =COUNTIFS(Data!D:D,'Absence Breakdown by Dept'!A86,Data!E:E,"Absent") -> 33 | C86: =COUNTIF(Data!D:D,'Absence Breakdown by Dept'!A86) -> 408 | D86: =B86/C86 -> 0.080882353
A87: Fri | B87: =COUNTIFS(Data!D:D,'Absence Breakdown by Dept'!A87,Data!E:E,"Absent") -> 33 | C87: =COUNTIF(Data!D:D,'Absence Breakdown by Dept'!A87) -> 408 | D87: =B87/C87 -> 0.080882353
